Traceback (most recent call last):
  File "C:\Users\Gunnar\.conda\envs\myJB\lib\site-packages\jupyter_cache\executors\utils.py", line 51, in single_nb_execution
    executenb(
  File "C:\Users\Gunnar\.conda\envs\myJB\lib\site-packages\nbclient\client.py", line 1204, in execute
    return NotebookClient(nb=nb, resources=resources, km=km, **kwargs).execute()
  File "C:\Users\Gunnar\.conda\envs\myJB\lib\site-packages\nbclient\util.py", line 84, in wrapped
    return just_run(coro(*args, **kwargs))
  File "C:\Users\Gunnar\.conda\envs\myJB\lib\site-packages\nbclient\util.py", line 62, in just_run
    return loop.run_until_complete(coro)
  File "C:\Users\Gunnar\.conda\envs\myJB\lib\asyncio\base_events.py", line 646, in run_until_complete
    return future.result()
  File "C:\Users\Gunnar\.conda\envs\myJB\lib\site-packages\nbclient\client.py", line 663, in async_execute
    await self.async_execute_cell(
  File "C:\Users\Gunnar\.conda\envs\myJB\lib\site-packages\nbclient\client.py", line 965, in async_execute_cell
    await self._check_raise_for_error(cell, cell_index, exec_reply)
  File "C:\Users\Gunnar\.conda\envs\myJB\lib\site-packages\nbclient\client.py", line 862, in _check_raise_for_error
    raise CellExecutionError.from_cell_and_msg(cell, exec_reply_content)
nbclient.exceptions.CellExecutionError: An error occurred while executing the following cell:
------------------
# pip install pandas
import os
import pandas as pd
import numpy as np
#from numpy import zeros


# LISTS
A = ['yep', 0 ,True,3]
A_1 = [0,1,2,3,4]

print('Lists comprise any data type A = ')
print(A)

#indexing A ########## NOT LIKE MATLAB indexing starts at 0
print('the first element in A')
print(A[0])

#checking the length of a list: ### function len
print('The length of A')
print(len(A))

# get the mean of a list (IF IT HAS NUMBERS)
print('Mean of A_1')
print(np.mean(A_1))
#print(np.mean(A))



------------------

[1;31m---------------------------------------------------------------------------[0m
[1;31mModuleNotFoundError[0m                       Traceback (most recent call last)
Input [1;32mIn [1][0m, in [0;36m<cell line: 3>[1;34m()[0m
[0;32m      1[0m [38;5;66;03m# pip install pandas[39;00m
[0;32m      2[0m [38;5;28;01mimport[39;00m [38;5;21;01mos[39;00m
[1;32m----> 3[0m [38;5;28;01mimport[39;00m [38;5;21;01mpandas[39;00m [38;5;28;01mas[39;00m [38;5;21;01mpd[39;00m
[0;32m      4[0m [38;5;28;01mimport[39;00m [38;5;21;01mnumpy[39;00m [38;5;28;01mas[39;00m [38;5;21;01mnp[39;00m
[0;32m      5[0m [38;5;66;03m#from numpy import zeros[39;00m
[0;32m      6[0m 
[0;32m      7[0m 
[0;32m      8[0m [38;5;66;03m# LISTS[39;00m

[1;31mModuleNotFoundError[0m: No module named 'pandas'
ModuleNotFoundError: No module named 'pandas'

